<?xml version="1.0" ?>
<sdf version="1.8">
    <world name="Moving_robot">
        <physics name="1ms" type="ignored">
            <max_step_size>0.001</max_step_size>
            <real_time_factor>1.0</real_time_factor>
        </physics>
        <!--PLUGINS-->
        <plugin
            filename="libignition-gazebo-physics-system.so"
            name="ignition::gazebo::systems::Physics">
        </plugin>
        <plugin
            filename="libignition-gazebo-user-commands-system.so"
            name="ignition::gazebo::systems::UserCommands">
        </plugin>
        <plugin
            filename="libignition-gazebo-scene-broadcaster-system.so"
            name="ignition::gazebo::systems::SceneBroadcaster">
        </plugin>
        <!--SCENE SETTING-->
        <light type="directional" name="sun">
            <cast_shadows>true</cast_shadows>
            <pose>0 0 10 0 0 0</pose>
            <diffuse>0.8 0.8 0.8 1</diffuse>
            <specular>0.2 0.2 0.2 1</specular>
            <attenuation>
                <range>1000</range>
                <constant>0.9</constant>
                <linear>0.01</linear>
                <quadratic>0.001</quadratic>
            </attenuation>
            <direction>-0.5 0.1 -0.9</direction>
        </light>

        <model name="ground_plane">
            <static>1</static>
            <static>true</static>
            <link name="link">
                <collision name="collision">
                <geometry>
                    <plane>
                    <normal>0 0 1</normal>
                    <size>100 100</size>
                    </plane>
                </geometry>
                <surface>
            <friction>
              <ode>
                <mu>100</mu>
                <mu2>50</mu2>
              </ode>
            </friction>
            <bounce/>
            <contact>
              <ode/>
            </contact>
          </surface>
          <max_contacts>10</max_contacts>
                </collision>
                <visual name="visual">
                <cast_shadows>0</cast_shadows>
                <geometry>
                    <plane>
                    <normal>0 0 1</normal>
                    <size>100 100</size>
                    </plane>
                </geometry>
                <material>
                    <ambient>0.8 0.8 0.8 1</ambient>
                    <diffuse>0.8 0.8 0.8 1</diffuse>
                    <specular>0.8 0.8 0.8 1</specular>
                </material>
                </visual>
                <velocity_decay>
          <linear>0</linear>
          <angular>0</angular>
        </velocity_decay>
        <self_collide>0</self_collide>
        <kinematic>0</kinematic>
        <gravity>1</gravity>
            </link>
        </model>
        <scene>
      <ambient>0.4 0.4 0.4 1</ambient>
      <background>0.7 0.7 0.7 1</background>
      <shadows>0</shadows>
    </scene>
    <physics type='ode'>
      <max_step_size>0.01</max_step_size>
      <real_time_factor>1</real_time_factor>
      <real_time_update_rate>0</real_time_update_rate>
      <gravity>0 0 -9.8</gravity>
    </physics>
    <state world_name='default'>
      <sim_time>0 0</sim_time>
      <real_time>0 44986</real_time>
      <wall_time>1377677575 940727583</wall_time>
    </state>
    <gui fullscreen='0'>
      <camera name='user_camera'>
        <pose>2.6 -1.69 12.2 0 1.56 3.14</pose>
        <view_controller>orbit</view_controller>
      </camera>
    </gui>

         <!--MAIN VEHICLE PART-->
        <model name='vehicle_blue' canonical_link='chassis'>
            <pose relative_to='world'>-10 10 0 0 0 -0.785</pose>   <!--the pose is relative to the world by default-->

            <link name='chassis'>
                <pose relative_to='__model__'>0.5 0 0.4 0 0 0</pose>
                <inertial> <!--inertial properties of the link mass, inertia matix-->
                    <mass>1.14395</mass>
                    <inertia>
                        <ixx>0.126164</ixx>
                        <ixy>0</ixy>
                        <ixz>0</ixz>
                        <iyy>0.416519</iyy>
                        <iyz>0</iyz>
                        <izz>0.481014</izz>
                    </inertia>
                </inertial>
                <visual name='visual'>
                    <geometry>
                        <box>
                            <size>2.0 1.0 0.5</size> <!--question: this size is in meter-->
                        </box>
                    </geometry>
                    <!--let's add color to our link-->
                    <material>
                        <ambient>0.0 0.0 1.0 1</ambient>
                        <diffuse>0.0 0.0 1.0 1</diffuse>
                        <specular>0.0 0.0 1.0 1</specular>
                    </material>
                </visual>
                <collision name='collision'> <!--todo: describe why we need the collision-->
                    <geometry>
                        <box>
                            <size>2.0 1.0 0.5</size>
                        </box>
                    </geometry>
                </collision>
            </link>

            <!--let's build the left wheel-->
            <link name='left_wheel'>
                <pose relative_to="chassis">-0.5 0.6 0 -1.5707 0 0</pose> <!--angles are in radian-->
                <inertial>
                    <mass>2</mass>
                    <inertia>
                        <ixx>0.145833</ixx>
                        <ixy>0</ixy>
                        <ixz>0</ixz>
                        <iyy>0.145833</iyy>
                        <iyz>0</iyz>
                        <izz>0.125</izz>
                    </inertia>
                </inertial>
                <visual name='visual'>
                    <geometry>
                        <cylinder>
                            <radius>0.4</radius>
                            <length>0.2</length>
                        </cylinder>
                    </geometry>
                    <material>
                        <ambient>1.0 0.0 0.0 1</ambient>
                        <diffuse>1.0 0.0 0.0 1</diffuse>
                        <specular>1.0 0.0 0.0 1</specular>
                    </material>
                </visual>
                <collision name='collision'>
                    <geometry>
                        <cylinder>
                            <radius>0.4</radius>
                            <length>0.2</length>
                        </cylinder>
                    </geometry>
                </collision>
            </link>

            <!--copy and paste for right wheel but change position-->
            <link name='right_wheel'>
                <pose relative_to="chassis">-0.5 -0.6 0 -1.5707 0 0</pose> <!--angles are in radian-->
                <inertial>
                    <mass>1</mass>
                    <inertia>
                        <ixx>0.145833</ixx>
                        <ixy>0</ixy>
                        <ixz>0</ixz>
                        <iyy>0.145833</iyy>
                        <iyz>0</iyz>
                        <izz>0.125</izz>
                    </inertia>
                </inertial>
                <visual name='visual'>
                    <geometry>
                        <cylinder>
                            <radius>0.4</radius>
                            <length>0.2</length>
                        </cylinder>
                    </geometry>
                    <material>
                        <ambient>1.0 0.0 0.0 1</ambient>
                        <diffuse>1.0 0.0 0.0 1</diffuse>
                        <specular>1.0 0.0 0.0 1</specular>
                    </material>
                </visual>
                <collision name='collision'>
                    <geometry>
                        <cylinder>
                            <radius>0.4</radius>
                            <length>0.2</length>
                        </cylinder>
                    </geometry>
                </collision>
            </link>

            <frame name="caster_frame" attached_to='chassis'>
                <pose>0.8 0 -0.2 0 0 0</pose>
            </frame>

            <!--caster wheel-->
            <link name='caster'>
                <pose relative_to='caster_frame'/>
                <inertial>
                    <mass>1</mass>
                    <inertia>
                        <ixx>0.1</ixx>
                        <ixy>0</ixy>
                        <ixz>0</ixz>
                        <iyy>0.1</iyy>
                        <iyz>0</iyz>
                        <izz>0.1</izz>
                    </inertia>
                </inertial>
                <visual name='visual'>
                    <geometry>
                        <sphere>
                            <radius>0.2</radius>
                        </sphere>
                    </geometry>
                    <material>
                        <ambient>0.0 1 0.0 1</ambient>
                        <diffuse>0.0 1 0.0 1</diffuse>
                        <specular>0.0 1 0.0 1</specular>
                    </material>
                </visual>
                <collision name='collision'>
                    <geometry>
                        <sphere>
                            <radius>0.2</radius>
                        </sphere>
                    </geometry>
                </collision>
            </link>


            <!--connecting these links together using joints-->
            <joint name='left_wheel_joint' type='revolute'> <!--continous joint is not supported yet-->
                <pose relative_to='left_wheel'/>
                <parent>chassis</parent>
                <child>left_wheel</child>
                <axis>
                    <xyz expressed_in='__model__'>0 1 0</xyz> <!--can be defined as any frame or even arbitrary frames-->
                    <limit>
                        <lower>-1.79769e+308</lower>    <!--negative infinity-->
                        <upper>1.79769e+308</upper>     <!--positive infinity-->
                    </limit>
                </axis>
            </joint>

            <joint name='right_wheel_joint' type='revolute'>
                <pose relative_to='right_wheel'/>
                <parent>chassis</parent>
                <child>right_wheel</child>
                <axis>
                    <xyz expressed_in='__model__'>0 1 0</xyz>
                    <limit>
                        <lower>-1.79769e+308</lower>    <!--negative infinity-->
                        <upper>1.79769e+308</upper>     <!--positive infinity-->
                    </limit>
                </axis>
            </joint>

            <!--different type of joints ball joint--> <!--defult value is the child-->
            <joint name='caster_wheel' type='ball'>
                <parent>chassis</parent>
                <child>caster</child>
            </joint>

            <!--diff drive plugin-->
            <plugin
                filename="libignition-gazebo-diff-drive-system.so"
                name="ignition::gazebo::systems::DiffDrive">
                <left_joint>left_wheel_joint</left_joint>
                <right_joint>right_wheel_joint</right_joint>
                <wheel_separation>1.2</wheel_separation>
                <wheel_radius>0.4</wheel_radius>
                <odom_publish_frequency>1</odom_publish_frequency>
                <topic>cmd_vel</topic>
            </plugin>
        </model>

<!-- Moving Forward, up arrow key, 16777235 -->
<!-- <plugin filename="libignition-gazebo-triggered-publisher-system.so"
        name="ignition::gazebo::systems::TriggeredPublisher">
    <input type="ignition.msgs.Int32" topic="/keyboard/keypress">
        <match field="data">16777235</match>
    </input>
    <output type="ignition.msgs.Twist" topic="/cmd_vel">
        linear: {x: 0.5}, angular: {z: 0.0}
    </output>
</plugin> -->
<!-- Moving Backward, down arrow key, 16777237-->
<!-- <plugin filename="libignition-gazebo-triggered-publisher-system.so"
        name="ignition::gazebo::systems::TriggeredPublisher">
    <input type="ignition.msgs.Int32" topic="/keyboard/keypress">
        <match field="data">16777237</match>
    </input>
    <output type="ignition.msgs.Twist" topic="/cmd_vel">
        linear: {x: -0.5}, angular: {z: 0.0}
    </output>
</plugin> -->
<!-- Moving Left, left arrow key, 16777234-->
<!-- <plugin filename="libignition-gazebo-triggered-publisher-system.so"
        name="ignition::gazebo::systems::TriggeredPublisher">
    <input type="ignition.msgs.Int32" topic="/keyboard/keypress">
        <match field="data">16777234</match>
    </input>
    <output type="ignition.msgs.Twist" topic="/cmd_vel">
        linear: {x: 0.0}, angular: {z: 0.5}
    </output>
</plugin> -->
<!-- Moving Right, right arrow key, 16777236-->
<!-- <plugin filename="libignition-gazebo-triggered-publisher-system.so"
        name="ignition::gazebo::systems::TriggeredPublisher">
    <input type="ignition.msgs.Int32" topic="/keyboard/keypress">
        <match field="data">16777236</match>
    </input>
    <output type="ignition.msgs.Twist" topic="/cmd_vel">
        linear: {x: 0.0}, angular: {z: -0.5}
    </output>
</plugin> -->
        
<actor name="actor1_walking">
    <skin>
        <filename>https://fuel.gazebosim.org/1.0/Mingfei/models/actor/tip/files/meshes/walk.dae</filename>
        <scale>1.0</scale>
    </skin>
    <animation name="walk">
        <filename>https://fuel.gazebosim.org/1.0/Mingfei/models/actor/tip/files/meshes/walk.dae</filename>
    </animation>
    <!-- <plugin filename="libignition-gazebo-touchplugin-system.so"
        name="ignition::gazebo::systems::TouchPlugin">
    <target>vehicle_blue</target>
    <namespace>goal</namespace>
    <time>0.001</time>
    <enabled>true</enabled>
</plugin> -->
<sensor name='sensor_contact' type='contact'>
    <contact>
        <collision>collision</collision>
    </contact>
</sensor>
    <script>
    <loop>true</loop>
    <delay_start>0.000000</delay_start>
    <auto_start>true</auto_start>
    <trajectory id="0" type="walk" tension="0.6">
            <waypoint>
                <time>0</time>
                <pose>-7 10 1 0 0 4.712</pose>
            </waypoint>
            <waypoint>
                <time>10</time>
                <pose>-7 -10 1 0 0 4.712</pose>
            </waypoint>
            <waypoint>
                <time>11</time>
                <pose>-7 -10 1 0 0 1.57</pose>
            </waypoint>
            <waypoint>
                <time>21</time>
                <pose>-7 10 1 0 0 1.57</pose>
            </waypoint>
            <waypoint>
                <time>22</time>
                <pose>-7 10 1 0 0 4.712</pose>
            </waypoint>
        </trajectory>
    </script>
</actor>

<actor name="actor2_walking">
    <skin>
        <filename>https://fuel.gazebosim.org/1.0/Mingfei/models/actor/tip/files/meshes/walk.dae</filename>
        <scale>1.0</scale>
    </skin>
    <animation name="walk">
        <filename>https://fuel.gazebosim.org/1.0/Mingfei/models/actor/tip/files/meshes/walk.dae</filename>
    </animation>
    <!-- <plugin filename="libignition-gazebo-touchplugin-system.so"
        name="ignition::gazebo::systems::TouchPlugin">
    <target>vehicle_blue</target>
    <namespace>goal</namespace>
    <time>0.001</time>
    <enabled>true</enabled>
</plugin> -->
<sensor name='sensor_contact' type='contact'>
    <contact>
        <collision>collision</collision>
    </contact>
</sensor>
    <script>
    <loop>true</loop>
    <delay_start>0.000000</delay_start>
    <auto_start>true</auto_start>
    <trajectory id="0" type="walk" tension="0.6">
            <waypoint>
                <time>0</time>
                <pose>0 -10 1 0 0 1.57</pose>
            </waypoint>
            <waypoint>
                <time>8</time>
                <pose>0 10 1 0 0 1.57</pose>
            </waypoint>
            <waypoint>
                <time>9</time>
                <pose>0 10 1 0 0 4.712</pose>
            </waypoint>
            <waypoint>
                <time>17</time>
                <pose>0 -10 1 0 0 4.712</pose>
            </waypoint>
            <waypoint>
                <time>18</time>
                <pose>0 -10 1 0 0 1.57</pose>
            </waypoint>
        </trajectory>
    </script>
</actor>

<actor name="actor3_walking">
    <skin>
        <filename>https://fuel.gazebosim.org/1.0/Mingfei/models/actor/tip/files/meshes/walk.dae</filename>
        <scale>1.0</scale>
    </skin>
    <animation name="walk">
        <filename>https://fuel.gazebosim.org/1.0/Mingfei/models/actor/tip/files/meshes/walk.dae</filename>
    </animation>
    <!-- <plugin filename="libignition-gazebo-touchplugin-system.so"
        name="ignition::gazebo::systems::TouchPlugin">
    <target>vehicle_blue</target>
    <namespace>goal</namespace>
    <time>0.001</time>
    <enabled>true</enabled>
</plugin> -->
<sensor name='sensor_contact' type='contact'>
    <contact>
        <collision>collision</collision>
    </contact>
</sensor>
    <script>
    <loop>true</loop>
    <delay_start>0.000000</delay_start>
    <auto_start>true</auto_start>
    <trajectory id="0" type="walk" tension="0.6">
            <waypoint>
                <time>0</time>
                <pose>7 10 1 0 0 4.712</pose>
            </waypoint>
            <waypoint>
                <time>6</time>
                <pose>7 -10 1 0 0 4.712</pose>
            </waypoint>
            <waypoint>
                <time>7</time>
                <pose>7 -10 1 0 0 1.57</pose>
            </waypoint>
            <waypoint>
                <time>13</time>
                <pose>7 10 1 0 0 1.57</pose>
            </waypoint>
            <waypoint>
                <time>14</time>
                <pose>7 10 1 0 0 4.712</pose>
            </waypoint>
        </trajectory>
    </script>
</actor>

        <!--OBSTACLE COURSE WALLS-->
        <model name='wall_1'>
        <plugin filename="libignition-gazebo-touchplugin-system.so"
        name="ignition::gazebo::systems::TouchPlugin">
    <target>vehicle_blue</target>
    <namespace>wall</namespace>
    <time>0.001</time>
    <enabled>true</enabled>
</plugin>
    <static>true</static>
    <pose>9 4 0 0 0 -0.166</pose><!--pose relative to the world-->
    <link name='box'>
        <pose/>
        <visual name='visual'>
            <geometry>
                <box>
                    <size>0.5 12.0 2.0</size>
                </box>
            </geometry>
            <!--let's add color to our link-->
            <material>
                <ambient>0.0 0.0 1.0 1</ambient>
                <diffuse>0.0 0.0 1.0 1</diffuse>
                <specular>0.0 0.0 1.0 1</specular>
            </material>
        </visual>
        <collision name='collision'>
            <geometry>
                <box>
                    <size>0.5 12.0 2.0</size>
                </box>
            </geometry>
        </collision>
        <sensor name='sensor_contact' type='contact'>
    <contact>
        <collision>collision</collision>
    </contact>
</sensor>
    </link>
</model>

<model name='wall_2'>
        <plugin filename="libignition-gazebo-touchplugin-system.so"
        name="ignition::gazebo::systems::TouchPlugin">
    <target>vehicle_blue</target>
    <namespace>wall</namespace>
    <time>0.001</time>
    <enabled>true</enabled>
</plugin>
    <static>true</static>
    <pose>2 4 0 0 0 -0.166</pose><!--pose relative to the world-->
    <link name='box'>
        <pose/>
        <visual name='visual'>
            <geometry>
                <box>
                    <size>0.5 12.0 2.0</size>
                </box>
            </geometry>
            <!--let's add color to our link-->
            <material>
                <ambient>0.0 0.0 1.0 1</ambient>
                <diffuse>0.0 0.0 1.0 1</diffuse>
                <specular>0.0 0.0 1.0 1</specular>
            </material>
        </visual>
        <collision name='collision'>
            <geometry>
                <box>
                    <size>0.5 12.0 2.0</size>
                </box>
            </geometry>
        </collision>
        <sensor name='sensor_contact' type='contact'>
    <contact>
        <collision>collision</collision>
    </contact>
</sensor>
    </link>
</model>

<model name='wall_3'>
        <plugin filename="libignition-gazebo-touchplugin-system.so"
        name="ignition::gazebo::systems::TouchPlugin">
    <target>vehicle_blue</target>
    <namespace>wall</namespace>
    <time>0.001</time>
    <enabled>true</enabled>
</plugin>
    <static>true</static>
    <pose>-5 4 0 0 0 -0.166</pose><!--pose relative to the world-->
    <link name='box'>
        <pose/>
        <visual name='visual'>
            <geometry>
                <box>
                    <size>0.5 12.0 2.0</size>
                </box>
            </geometry>
            <!--let's add color to our link-->
            <material>
                <ambient>0.0 0.0 1.0 1</ambient>
                <diffuse>0.0 0.0 1.0 1</diffuse>
                <specular>0.0 0.0 1.0 1</specular>
            </material>
        </visual>
        <collision name='collision'>
            <geometry>
                <box>
                    <size>0.5 12.0 2.0</size>
                </box>
            </geometry>
        </collision>
        <sensor name='sensor_contact' type='contact'>
    <contact>
        <collision>collision</collision>
    </contact>
</sensor>
    </link>
</model>

<model name='wall_4'>
        <plugin filename="libignition-gazebo-touchplugin-system.so"
        name="ignition::gazebo::systems::TouchPlugin">
    <target>vehicle_blue</target>
    <namespace>wall</namespace>
    <time>0.001</time>
    <enabled>true</enabled>
</plugin>
    <static>true</static>
    <pose>5 -4 0 0 0 0.166</pose><!--pose relative to the world-->
    <link name='box'>
        <pose/>
        <visual name='visual'>
            <geometry>
                <box>
                    <size>0.5 12.0 2.0</size>
                </box>
            </geometry>
            <!--let's add color to our link-->
            <material>
                <ambient>0.0 0.0 1.0 1</ambient>
                <diffuse>0.0 0.0 1.0 1</diffuse>
                <specular>0.0 0.0 1.0 1</specular>
            </material>
        </visual>
        <collision name='collision'>
            <geometry>
                <box>
                    <size>0.5 12.0 2.0</size>
                </box>
            </geometry>
        </collision>
        <sensor name='sensor_contact' type='contact'>
    <contact>
        <collision>collision</collision>
    </contact>
</sensor>
    </link>
</model>

<model name='wall_5'>
        <plugin filename="libignition-gazebo-touchplugin-system.so"
        name="ignition::gazebo::systems::TouchPlugin">
    <target>vehicle_blue</target>
    <namespace>wall</namespace>
    <time>0.001</time>
    <enabled>true</enabled>
</plugin>
    <static>true</static>
    <pose>-2 -4 0 0 0 0.166</pose><!--pose relative to the world-->
    <link name='box'>
        <pose/>
        <visual name='visual'>
            <geometry>
                <box>
                    <size>0.5 12.0 2.0</size>
                </box>
            </geometry>
            <!--let's add color to our link-->
            <material>
                <ambient>0.0 0.0 1.0 1</ambient>
                <diffuse>0.0 0.0 1.0 1</diffuse>
                <specular>0.0 0.0 1.0 1</specular>
            </material>
        </visual>
        <collision name='collision'>
            <geometry>
                <box>
                    <size>0.5 12.0 2.0</size>
                </box>
            </geometry>
        </collision>
        <sensor name='sensor_contact' type='contact'>
    <contact>
        <collision>collision</collision>
    </contact>
</sensor>
    </link>
</model>

<model name='wall_6'>
        <plugin filename="libignition-gazebo-touchplugin-system.so"
        name="ignition::gazebo::systems::TouchPlugin">
    <target>vehicle_blue</target>
    <namespace>wall</namespace>
    <time>0.001</time>
    <enabled>true</enabled>
</plugin>
    <static>true</static>
    <pose>-9 -4 0 0 0 0.166</pose><!--pose relative to the world-->
    <link name='box'>
        <pose/>
        <visual name='visual'>
            <geometry>
                <box>
                    <size>0.5 12.0 2.0</size>
                </box>
            </geometry>
            <!--let's add color to our link-->
            <material>
                <ambient>0.0 0.0 1.0 1</ambient>
                <diffuse>0.0 0.0 1.0 1</diffuse>
                <specular>0.0 0.0 1.0 1</specular>
            </material>
        </visual>
        <collision name='collision'>
            <geometry>
                <box>
                    <size>0.5 12.0 2.0</size>
                </box>
            </geometry>
        </collision>
        <sensor name='sensor_contact' type='contact'>
    <contact>
        <collision>collision</collision>
    </contact>
</sensor>
    </link>
</model>

<model name='goal_point'>
        <plugin filename="libignition-gazebo-touchplugin-system.so"
        name="ignition::gazebo::systems::TouchPlugin">
    <target>vehicle_blue</target>
    <namespace>goal</namespace>
    <time>0.001</time>
    <enabled>true</enabled>
</plugin>
    <static>true</static>
    <pose>10 -10 0 0 0 0</pose><!--pose relative to the world-->
    <link name='box'>
        <pose/>
        <visual name='visual'>
            <geometry>
                <box>
                    <size>2.0 2.0 2.0</size>
                </box>
            </geometry>
            <!--let's add color to our link-->
            <material>
                <ambient>0.0 0.0 1.0 1</ambient>
                <diffuse>0.0 0.0 1.0 1</diffuse>
                <specular>0.0 0.0 1.0 1</specular>
            </material>
        </visual>
        <collision name='collision'>
            <geometry>
                <box>
                    <size>2.0 2.0 2.0</size>
                </box>
            </geometry>
        </collision>
        <sensor name='sensor_contact' type='contact'>
    <contact>
        <collision>collision</collision>
    </contact>
</sensor>
    </link>
</model>
    </world>
</sdf>